<span>
    <div class="example_summary"><span><span> Demonstrate how to handle the error of a sequence of processors in a for-comprehension.  <p> Since onFailure returns a potential default value it can only be used to catch the exception raised by a single processor.  This example demonstrates how to use onFailure to handle the exceptions raised by any of several processors </p> </span></span></div>
    <div class="example_code"><pre class="brush: scala">
    import scalax.io.Resource
    import scalax.io.processing.Processor

    val bytes = Resource.fromFile(&quot;somefile&quot;).bytes

    val return1OnError:PartialFunction[Throwable,Option[Char]] = {
      case _ =&gt; Some(1.toChar)
    }
    val process:Processor[Char] = for {
      processor &lt;- bytes.processor

      // create a new processor that consists of all the processor
      // that need to have error handling
      group = for {
        byte1 &lt;- processor.next
        byte2 &lt;- processor.next
      } yield {byte1 + byte2 toChar}
      // add the handler to the new processor
      finalValue &lt;- group onFailure return1OnError
    } yield {
      finalValue
    }

    process.acquireAndGet{ char =&gt;
      // do something with char
    }

    // similarly the resulting processor can have an error handler attached
    process onFailure return1OnError acquireAndGet {char =&gt;
      // do something
    }
  </pre></div>
    <span></span>
  </span>